<?xml version="1.0" encoding="utf-8"?>
<robot
  name="rover">
  <link
    name="base_link">
    <inertial>
      <origin
        xyz="-0.29995 0.2 0.041752"
        rpy="0 0 0" />
      <mass
        value="13.103" />
      <inertia
        ixx="0.24866"
        ixy="1.4075E-09"
        ixz="-0.0006327"
        iyy="0.61245"
        iyz="5.582E-09"
        izz="0.83734" />
    </inertial>
    <visual>
      <origin
        xyz="0 0 0"
        rpy="0 0 0" />
      <geometry>
        <mesh
          filename="package://rover/meshes/base_link.STL" />
      </geometry>
      <material
        name="">
        <color
          rgba="0.79216 0.81961 0.93333 1" />
      </material>
    </visual>
    <collision>
      <origin
        xyz="0 0 0"
        rpy="0 0 0" />
      <geometry>
        <mesh
          filename="package://rover/meshes/base_link.STL" />
      </geometry>
    </collision>
  </link>
  <link
    name="rear_wheels">
    <inertial>
      <origin
        xyz="-1.1102E-16 2.2204E-16 -0.3"
        rpy="0 0 0" />
      <mass
        value="3.8893" />
      <inertia
        ixx="0.026151"
        ixy="3.5479E-19"
        ixz="-2.0965E-19"
        iyy="0.026151"
        iyz="-1.1357E-18"
        izz="0.020788" />
    </inertial>
    <visual>
      <origin
        xyz="0 0 0"
        rpy="0 0 0" />
      <geometry>
        <mesh
          filename="package://rover/meshes/rear_wheels.STL" />
      </geometry>
      <material
        name="">
        <color
          rgba="0.79216 0.81961 0.93333 1" />
      </material>
    </visual>
    <collision>
      <origin
        xyz="0 0 0"
        rpy="0 0 0" />
      <geometry>
        <mesh
          filename="package://rover/meshes/rear_wheels.STL" />
      </geometry>
    </collision>
  </link>
  <joint
    name="rear_wheel_joint"
    type="continuous">
    <origin
      xyz="-0.52 -0.1 0.022"
      rpy="1.5708 0 0" />
    <parent
      link="base_link" />
    <child
      link="rear_wheels" />
    <axis
      xyz="0 0 1" />
  </joint>
  <link
    name="front_wheels">
    <inertial>
      <origin
        xyz="-1.8874E-15 6.6613E-16 -0.3"
        rpy="0 0 0" />
      <mass
        value="3.8893" />
      <inertia
        ixx="0.026151"
        ixy="9.817E-19"
        ixz="7.6731E-19"
        iyy="0.026151"
        iyz="1.0524E-19"
        izz="0.020788" />
    </inertial>
    <visual>
      <origin
        xyz="0 0 0"
        rpy="0 0 0" />
      <geometry>
        <mesh
          filename="package://rover/meshes/front_wheels.STL" />
      </geometry>
      <material
        name="">
        <color
          rgba="0.79216 0.81961 0.93333 1" />
      </material>
    </visual>
    <collision>
      <origin
        xyz="0 0 0"
        rpy="0 0 0" />
      <geometry>
        <mesh
          filename="package://rover/meshes/front_wheels.STL" />
      </geometry>
    </collision>
  </link>
  <joint
    name="front_wheel_joint"
    type="continuous">
    <origin
      xyz="-0.07 -0.1 0.022"
      rpy="1.5708 0 0" />
    <parent
      link="base_link" />
    <child
      link="front_wheels" />
    <axis
      xyz="0 0 1" />
  </joint>

  <transmission name="rear_drive_trans">
     <type>transmission_interface/SimpleTransmission</type>
     <joint name="rear_wheel_joint">
       <hardwareInterface>hardware_interface/VelocityJointInterface</hardwareInterface>
     </joint>
     <actuator name="rear_motor">
       <mechanicalReduction>1</mechanicalReduction>
       <hardwareInterface>hardware_interface/VelocityJointInterface</hardwareInterface>
     </actuator>
  </transmission>
  <transmission name="front_right_trans">
     <type>transmission_interface/SimpleTransmission</type>
     <joint name="front_right_joint">
       <hardwareInterface>hardware_interface/VelocityJointInterface</hardwareInterface>
     </joint>
     <actuator name="f_r_motor">
       <mechanicalReduction>1</mechanicalReduction>
       <hardwareInterface>hardware_interface/VelocityJointInterface</hardwareInterface>
     </actuator>
  </transmission>
  <transmission name="front_left_trans">
     <type>transmission_interface/SimpleTransmission</type>
     <joint name="front_left_joint">
       <hardwareInterface>hardware_interface/VelocityJointInterface</hardwareInterface>
     </joint>
     <actuator name="f_l_motor">
       <mechanicalReduction>1</mechanicalReduction>
       <hardwareInterface>hardware_interface/VelocityJointInterface</hardwareInterface>
     </actuator>
  </transmission>
</robot>
