<?xml version="1.0"?>

<robot name="robot_arm">

  <link name="world">
    <origin xyz="0 0 0" rpy="0 0 0"  />
  </link>

  <link name="arm_base">
    <inertial>
      <origin
        xyz="7.7128E-09 -0.063005 -3.01969999961422E-08"
        rpy="0 0 0" />
      <mass
        value="1.6004" />
      <inertia
        ixx="0.00552196561445819"
        ixy="7.9550614501301E-10"
        ixz="-1.34378458924839E-09"
        iyy="0.00352397447953875"
        iyz="-1.10071809773382E-08"
        izz="0.00553739792746489" />
    </inertial>
    <visual>
      <origin
        xyz="0 0 0"
        rpy="0 0 0" />
      <geometry>
        <mesh filename="package://robot_description/meshes/arm_base.stl" />
      </geometry>
      <material
        name="">
        <color
          rgba="0.79216 0.81961 0.93333 1" />
      </material>
    </visual>
    <collision>
      <origin
        xyz="0 0 0"
        rpy="0 0 0" />
      <geometry>
        <mesh filename="package://robot_description/meshes/arm_base.stl" />
      </geometry>
    </collision>
</link>

<!--######################################################################-->
<joint name="arm_base_joint" type="continuous">
  <axis xyz="0 0 1"/>
  <parent link="world"/>
  <child link="arm_base"/>
  <origin rpy="0 0 0" xyz="0.0 0.0 0.1"/>
</joint>

</robot>
